<?xml version="1.0" encoding="utf-8"?>
<!-- This URDF was automatically created by SolidWorks to URDF Exporter! Originally created by Stephen Brawner (brawner@gmail.com) 
     Commit Version: 1.6.0-1-g15f4949  Build Version: 1.6.7594.29634
     For more information, please see http://wiki.ros.org/sw_urdf_exporter -->
<robot
  name="gp7_robot">

  <gazebo>
    <plugin
      filename="libgz_ros2_control-system.so"
      name="gz_ros2_control::GazeboSimROS2ControlPlugin">
      <parameters>/home/kiran_gunathilaka/development/ros/robotic_manipulator_simulation/src/gp7_robot/config/gp7_controllers.yaml</parameters>
      <controller_manager_name>controller_manager</controller_manager_name>
      <hold_joints>true</hold_joints>
      <position_proportional_gain>0.1</position_proportional_gain>
    </plugin>
  </gazebo>

  <ros2_control name="GazeboSimSystem" type="system">
    <hardware>
      <plugin>gz_ros2_control/GazeboSimSystem</plugin>
    </hardware>
    <joint name="joint1">
      <command_interface name="position"/>
      <state_interface name="position"/>
      <state_interface name="velocity"/>
      <state_interface name="effort"/>
    </joint>
    <joint name="joint2">
      <command_interface name="position"/>
      <state_interface name="position"/>
      <state_interface name="velocity"/>
      <state_interface name="effort"/>
    </joint>
    <joint name="joint3">
      <command_interface name="position"/>
      <state_interface name="position"/>
      <state_interface name="velocity"/>
      <state_interface name="effort"/>
    </joint>
    <joint name="joint4">
      <command_interface name="position"/>
      <state_interface name="position"/>
      <state_interface name="velocity"/>
      <state_interface name="effort"/>
    </joint>
    <joint name="joint5">
      <command_interface name="position"/>
      <state_interface name="position"/>
      <state_interface name="velocity"/>
      <state_interface name="effort"/>
    </joint>
    <joint name="joint6">
      <command_interface name="position"/>
      <state_interface name="position"/>
      <state_interface name="velocity"/>
      <state_interface name="effort"/>
    </joint>
  </ros2_control>
  
  <link name="world"/>
  <joint name="world_to_base" type="fixed">
    <parent link="world"/>
    <child link="base_link"/>
    <origin xyz="0 0 0" rpy="0 0 0"/>
  </joint>
  <!-- Your original base_link definition starts here -->
  <link name="base_link">
    <inertial>
      <origin xyz="-0.0061643 6.0941E-07 0.083158" rpy="0 0 0" />
      <mass value="5.2154" />
      <inertia
        ixx="0.026026"
        ixy="-2.5924E-05"
        ixz="0.00013984"
        iyy="0.025295"
        iyz="-4.7677E-05"
        izz="0.021721" />
    </inertial>
    <visual>
      <origin xyz="0 0 0" rpy="0 0 0" />
      <geometry>
        <mesh filename="package://gp7_robot/meshes/base_link.STL" />
      </geometry>
      <material name="">
        <color rgba="1 0 0 1" />
      </material>
    </visual>
    <collision>
      <origin xyz="0 0 0" rpy="0 0 0" />
      <geometry>
        <mesh filename="package://gp7_robot/meshes/base_link.STL" />
      </geometry>
    </collision>
  </link>
  <link
    name="link1">
    <inertial>
      <origin
        xyz="0.015549 -0.0019593 0.095449"
        rpy="0 0 0" />
      <mass
        value="2.9447" />
      <inertia
        ixx="0.011192"
        ixy="9.0245E-05"
        ixz="-0.0021643"
        iyy="0.011936"
        iyz="0.00025509"
        izz="0.0088687" />
    </inertial>
    <visual>
      <origin
        xyz="0 0 0"
        rpy="0 0 0" />
      <geometry>
        <mesh
          filename="package://gp7_robot/meshes/link1.STL" />
      </geometry>
      <material
        name="">
        <color
          rgba="0 1 0 1" />
      </material>
    </visual>
    <collision>
      <origin
        xyz="0 0 0"
        rpy="0 0 0" />
      <geometry>
        <mesh
          filename="package://gp7_robot/meshes/link1.STL" />
      </geometry>
    </collision>
  </link>
  <joint
    name="joint1"
    type="revolute">
    <origin
      xyz="-0.000595342695521883 0 0.1829"
      rpy="0 0 0" />
    <parent
      link="base_link" />
    <child
      link="link1" />
    <axis
      xyz="0 0 1" />
    <!-- S axis: ±170°, 375 °/s -->
    <limit
      lower="-2.96706"
      upper="2.96706"
      effort="0"
      velocity="6.54499" />
  </joint>
  <link
    name="link2">
    <inertial>
      <origin
        xyz="0.098772 0.17038 -0.071798"
        rpy="0 0 0" />
      <mass
        value="6.2405" />
      <inertia
        ixx="0.11256"
        ixy="-0.034136"
        ixz="-0.00014143"
        iyy="0.041497"
        iyz="-0.0004635"
        izz="0.11052" />
    </inertial>
    <visual>
      <origin
        xyz="0 0 0"
        rpy="0 0 0" />
      <geometry>
        <mesh
          filename="package://gp7_robot/meshes/link2.STL" />
      </geometry>
      <material
        name="">
        <color
          rgba="0 0 1 1" />
      </material>
    </visual>
    <collision>
      <origin
        xyz="0 0 0"
        rpy="0 0 0" />
      <geometry>
        <mesh
          filename="package://gp7_robot/meshes/link2.STL" />
      </geometry>
    </collision>
  </link>
  <joint
    name="joint2"
    type="revolute">
    <origin
      xyz="0.0481152180218847 0.0668500247537757 0.135500000000094"
      rpy="1.57079632679473 0 3.0248336337098" />
    <parent
      link="link1" />
    <child
      link="link2" />
    <axis
      xyz="0 0 1" />
    <!-- L axis: +145° / -65°, 315 °/s -->
    <limit
      lower="-1.13446"
      upper="2.53073"
      effort="0"
      velocity="5.49779" />
  </joint>
  <link
    name="link3">
    <inertial>
      <origin
        xyz="-0.024876 0.006034 -0.072854"
        rpy="0 0 0" />
      <mass
        value="2.8492" />
      <inertia
        ixx="0.0078502"
        ixy="-0.0010799"
        ixz="4.7231E-05"
        iyy="0.0073158"
        iyz="-1.0093E-05"
        izz="0.0077915" />
    </inertial>
    <visual>
      <origin
        xyz="0 0 0"
        rpy="0 0 0" />
      <geometry>
        <mesh
          filename="package://gp7_robot/meshes/link3.STL" />
      </geometry>
      <material
        name="">
        <color
          rgba="1 1 0 1" />
      </material>
    </visual>
    <collision>
      <origin
        xyz="0 0 0"
        rpy="0 0 0" />
      <geometry>
        <mesh
          filename="package://gp7_robot/meshes/link3.STL" />
      </geometry>
    </collision>
  </link>
  <joint
    name="joint3"
    type="revolute">
    <origin
      xyz="0.166975951159858 0.412485189717141 0"
      rpy="0 0 -1.57079632679492" />
    <parent
      link="link2" />
    <child
      link="link3" />
    <axis
      xyz="0 0 1" />
    <!-- U axis: +190° / -70°, 410 °/s -->
    <limit
      lower="-1.22173"
      upper="3.31613"
      effort="0"
      velocity="7.15585" />
  </joint>
  <link
    name="link4">
    <inertial>
      <origin
        xyz="0.00013611 0.0001738 0.16677"
        rpy="0 0 0" />
      <mass
        value="2.7554" />
      <inertia
        ixx="0.010092"
        ixy="-7.0814E-05"
        ixz="-3.5239E-05"
        iyy="0.010778"
        iyz="0.00031664"
        izz="0.0030859" />
    </inertial>
    <visual>
      <origin
        xyz="0 0 0"
        rpy="0 0 0" />
      <geometry>
        <mesh
          filename="package://gp7_robot/meshes/link4.STL" />
      </geometry>
      <material
        name="">
        <color
          rgba="1 0 1 1" />
      </material>
    </visual>
    <collision>
      <origin
        xyz="0 0 0"
        rpy="0 0 0" />
      <geometry>
        <mesh
          filename="package://gp7_robot/meshes/link4.STL" />
      </geometry>
    </collision>
  </link>
  <joint
    name="joint4"
    type="revolute">
    <origin
      xyz="-0.00319297470642954 -0.0884918352576554 -0.0720000000000005"
      rpy="-1.57079632679483 -0.272786020633957 -2.70896107573833" />
    <parent
      link="link3" />
    <child
      link="link4" />
    <axis
      xyz="0 0 1" />
    <!-- R axis: ±190°, 550 °/s -->
    <limit
      lower="-3.31613"
      upper="3.31613"
      effort="0"
      velocity="9.59931" />
  </joint>
  <link
    name="link5">
    <inertial>
      <origin
        xyz="0.0002539 0.01321 -0.015248"
        rpy="0 0 0" />
      <mass
        value="0.24589" />
      <inertia
        ixx="0.00013953"
        ixy="-2.1178E-06"
        ixz="1.9621E-07"
        iyy="0.00015684"
        iyz="-1.2921E-06"
        izz="0.00018562" />
    </inertial>
    <visual>
      <origin
        xyz="0 0 0"
        rpy="0 0 0" />
      <geometry>
        <mesh
          filename="package://gp7_robot/meshes/link5.STL" />
      </geometry>
      <material
        name="">
        <color
          rgba="0 1 1 1" />
      </material>
    </visual>
    <collision>
      <origin
        xyz="0 0 0"
        rpy="0 0 0" />
      <geometry>
        <mesh
          filename="package://gp7_robot/meshes/link5.STL" />
      </geometry>
    </collision>
  </link>
  <joint
    name="joint5"
    type="revolute">
    <origin
      xyz="-0.00132428368504911 0.0134348901237163 0.361000000001776"
      rpy="1.57079632679489 0.0421986683723227 -3.04333955815242" />
    <parent
      link="link4" />
    <child
      link="link5" />
    <axis
      xyz="0 0 1" />
    <!-- B axis: ±135°, 550 °/s -->
    <limit
      lower="-2.35619"
      upper="2.35619"
      effort="0"
      velocity="9.59931" />
  </joint>
  <link
    name="EE">
    <inertial>
      <origin
        xyz="-0.0017106 -0.0011481 0.049992"
        rpy="0 0 0" />
      <mass
        value="0.12078" />
      <inertia
        ixx="3.8972E-05"
        ixy="-2.7372E-06"
        ixz="-2.0092E-06"
        iyy="4.0598E-05"
        iyz="-1.6891E-06"
        izz="4.5899E-05" />
    </inertial>
    <visual>
      <origin
        xyz="0 0 0"
        rpy="0 0 0" />
      <geometry>
        <mesh
          filename="package://gp7_robot/meshes/EE.STL" />
      </geometry>
      <material
        name="">
        <color
          rgba="0.5 0.5 0.5 1" />
      </material>
    </visual>
    <collision>
      <origin
        xyz="0 0 0"
        rpy="0 0 0" />
      <geometry>
        <mesh
          filename="package://gp7_robot/meshes/EE.STL" />
      </geometry>
    </collision>
  </link>
  <joint
    name="joint6"
    type="continuous">
    <origin
      xyz="0 0.0674999999997865 -0.0134999999999023"
      rpy="1.57079632697687 1.39265583816902 -3.14159265335474" />
    <parent
      link="link5" />
    <child
      link="EE" />
    <axis
      xyz="0 0 1" />
  </joint>

</robot>